{"trial_id": "0001", "hyperparameters": {"space": [{"class_name": "Int", "config": {"name": "units", "default": null, "conditions": [], "min_value": 32, "max_value": 256, "step": 16, "sampling": "linear"}}, {"class_name": "Choice", "config": {"name": "learning_rate", "default": 0.01, "conditions": [], "values": [0.01, 0.001], "ordered": true}}], "values": {"units": 64, "learning_rate": 0.001, "tuner/epochs": 2, "tuner/initial_epoch": 0, "tuner/bracket": 2, "tuner/round": 0}}, "metrics": {"metrics": {}}, "score": null, "best_step": 0, "status": "FAILED", "message": "Traceback (most recent call last):\n  File \"C:\\Users\\ADMIN\\AppData\\Roaming\\Python\\Python310\\site-packages\\keras_tuner\\engine\\base_tuner.py\", line 270, in _try_run_and_update_trial\n    self._run_and_update_trial(trial, *fit_args, **fit_kwargs)\n  File \"C:\\Users\\ADMIN\\AppData\\Roaming\\Python\\Python310\\site-packages\\keras_tuner\\engine\\base_tuner.py\", line 235, in _run_and_update_trial\n    results = self.run_trial(trial, *fit_args, **fit_kwargs)\n  File \"C:\\Users\\ADMIN\\AppData\\Roaming\\Python\\Python310\\site-packages\\keras_tuner\\tuners\\hyperband.py\", line 425, in run_trial\n    return super().run_trial(trial, *fit_args, **fit_kwargs)\n  File \"C:\\Users\\ADMIN\\AppData\\Roaming\\Python\\Python310\\site-packages\\keras_tuner\\engine\\tuner.py\", line 287, in run_trial\n    obj_value = self._build_and_fit_model(trial, *args, **copied_kwargs)\n  File \"C:\\Users\\ADMIN\\AppData\\Roaming\\Python\\Python310\\site-packages\\keras_tuner\\engine\\tuner.py\", line 214, in _build_and_fit_model\n    results = self.hypermodel.fit(hp, model, *args, **kwargs)\n  File \"C:\\Users\\ADMIN\\AppData\\Roaming\\Python\\Python310\\site-packages\\keras_tuner\\engine\\hypermodel.py\", line 144, in fit\n    return model.fit(*args, **kwargs)\n  File \"C:\\Users\\ADMIN\\AppData\\Roaming\\Python\\Python310\\site-packages\\keras\\utils\\traceback_utils.py\", line 70, in error_handler\n    raise e.with_traceback(filtered_tb) from None\n  File \"C:\\Users\\ADMIN\\AppData\\Roaming\\Python\\Python310\\site-packages\\tensorflow\\python\\eager\\execute.py\", line 52, in quick_execute\n    tensors = pywrap_tfe.TFE_Py_Execute(ctx._handle, device_name, op_name,\ntensorflow.python.framework.errors_impl.InvalidArgumentError: Graph execution error:\n\nInvalid PNG data, size 319585\n\t [[{{node decode_image/DecodeImage}}]]\n\t [[IteratorGetNext]] [Op:__inference_train_function_5112]\n"}